Workbook

Sheet Customer Names
A1: Customer ID | B1: name | C1: Title | D1: First Name | E1: Last Name
A2: Id1 | B2: Hawks, Ms. Kelly | C2: Ms. | D2: Hawks | E2: Kelly
A3: Id2 | B3: Lehner, Mr. Matthew D | C3: Mr. | D3: Lehner | E3: Matthew D
A4: Id3 | B4: Lu, Mr. Phil | C4: Mr. | D4: Lu | E4: Phil
A5: Id4 | B5: Osborne, Ms. Kelsey | C5: Ms. | D5: Osborne | E5: Kelsey
A6: Id5 | B6: Kadala, Ms. Kristyn | C6: Ms. | D6: Kadala | E6: Kristyn
A7: Id6 | B7: Baker, Mr. Russell B. | C7: Mr. | D7: Baker | E7: Russell B.
A8: Id7 | B8: Macpherson, Mr. Scott | C8: Mr. | D8: Macpherson | E8: Scott
A9: Id8 | B9: Hallman, Mr. Stephen | C9: Mr. | D9: Hallman | E9: Stephen
A10: Id9 | B10: Moran, Mr. Patrick R. | C10: Mr. | D10: Moran | E10: Patrick R.
A11: Id10 | B11: Benner, Ms. Brooke N. | C11: Ms. | D11: Benner | E11: Brooke N.
A12: Id11 | B12: Fierro Vargas, Ms. Paola Andrea | C12: Ms. | D12: Fierro Vargas | E12: Paola Andrea
... A2336: Id2335 | B2336: German, Mr. Aaron K | C2336: Mr. | D2336: German | E2336: Aaron K

Sheet Medical Examinations
A1: Customer ID | B1: BMI | C1: Weight Status | D1: HBA1C | E1: Diabetes status | F1: Heart Issues | G1: Any Transplants | H1: Cancer history | I1: NumberOfMajorSurgeries | J1: No of surgeries Imputed | K1: smoker | L1: Smoker Imputed
A2: Id1 | B2: 47.41 | C2: =IF(B2<18.5,"Underweight",IF(B2<25,"Normal weight", IF(B2<30,"Overweight","Obesity"))) -> Obesity | D2: 7.47 | E2: =IF(D2<5.7,"Normal",IF(D2<6.5,"Pre-diabetes","Diabetes")) -> Diabetes | F2: No | G2: No | H2: No | I2: No major surgery | J2: =IF(I2="No major surgery",0,I2) -> 0 | K2: yes | L2: =IF(K2="?","No",K2) -> yes
A3: Id2 | B3: 30.36 | C3: =IF(B3<18.5,"Underweight",IF(B3<25,"Normal weight", IF(B3<30,"Overweight","Obesity"))) -> Obesity | D3: 5.77 | E3: =IF(D3<5.7,"Normal",IF(D3<6.5,"Pre-diabetes","Diabetes")) -> Pre-diabetes | F3: No | G3: No | H3: No | I3: No major surgery | J3: =IF(I3="No major surgery",0,I3) -> 0 | K3: yes | L3: =IF(K3="?","No",K3) -> yes
A4: Id3 | B4: 34.485 | C4: =IF(B4<18.5,"Underweight",IF(B4<25,"Normal weight", IF(B4<30,"Overweight","Obesity"))) -> Obesity | D4: 11.87 | E4: =IF(D4<5.7,"Normal",IF(D4<6.5,"Pre-diabetes","Diabetes")) -> Diabetes | F4: yes | G4: No | H4: No | I4: 2 | J4: =IF(I4="No major surgery",0,I4) -> 2 | K4: yes | L4: =IF(K4="?","No",K4) -> yes | M4: number of missing values marked with '?' | N4: =COUNTIF(A1:K2336,"?") -> 2
A5: Id4 | B5: 38.095 | C5: =IF(B5<18.5,"Underweight",IF(B5<25,"Normal weight", IF(B5<30,"Overweight","Obesity"))) -> Obesity | D5: 6.05 | E5: =IF(D5<5.7,"Normal",IF(D5<6.5,"Pre-diabetes","Diabetes")) -> Pre-diabetes | F5: No | G5: No | H5: No | I5: No major surgery | J5: =IF(I5="No major surgery",0,I5) -> 0 | K5: yes | L5: =IF(K5="?","No",K5) -> yes
A6: Id5 | B6: 35.53 | C6: =IF(B6<18.5,"Underweight",IF(B6<25,"Normal weight", IF(B6<30,"Overweight","Obesity"))) -> Obesity | D6: 5.45 | E6: =IF(D6<5.7,"Normal",IF(D6<6.5,"Pre-diabetes","Diabetes")) -> Normal | F6: No | G6: No | H6: No | I6: No major surgery | J6: =IF(I6="No major surgery",0,I6) -> 0 | K6: yes | L6: =IF(K6="?","No",K6) -> yes | M6: No. of yes in smoker | N6: =COUNTIF(K2:K2336,"yes") -> 488
A7: Id6 | B7: 32.8 | C7: =IF(B7<18.5,"Underweight",IF(B7<25,"Normal weight", IF(B7<30,"Overweight","Obesity"))) -> Obesity | D7: 6.59 | E7: =IF(D7<5.7,"Normal",IF(D7<6.5,"Pre-diabetes","Diabetes")) -> Diabetes | F7: No | G7: No | H7: No | I7: No major surgery | J7: =IF(I7="No major surgery",0,I7) -> 0 | K7: yes | L7: =IF(K7="?","No",K7) -> yes | M7: No. of No in smoker | N7: =COUNTIF(K2:K2336,"no") -> 1845
A8: Id7 | B8: 36.4 | C8: =IF(B8<18.5,"Underweight",IF(B8<25,"Normal weight", IF(B8<30,"Overweight","Obesity"))) -> Obesity | D8: 6.07 | E8: =IF(D8<5.7,"Normal",IF(D8<6.5,"Pre-diabetes","Diabetes")) -> Pre-diabetes | F8: No | G8: No | H8: No | I8: No major surgery | J8: =IF(I8="No major surgery",0,I8) -> 0 | K8: yes | L8: =IF(K8="?","No",K8) -> yes
A9: Id8 | B9: 36.96 | C9: =IF(B9<18.5,"Underweight",IF(B9<25,"Normal weight", IF(B9<30,"Overweight","Obesity"))) -> Obesity | D9: 7.93 | E9: =IF(D9<5.7,"Normal",IF(D9<6.5,"Pre-diabetes","Diabetes")) -> Diabetes | F9: No | G9: No | H9: No | I9: 3 | J9: =IF(I9="No major surgery",0,I9) -> 3 | K9: yes | L9: =IF(K9="?","No",K9) -> yes
A10: Id9 | B10: 41.14 | C10: =IF(B10<18.5,"Underweight",IF(B10<25,"Normal weight", IF(B10<30,"Overweight","Obesity"))) -> Obesity | D10: 9.58 | E10: =IF(D10<5.7,"Normal",IF(D10<6.5,"Pre-diabetes","Diabetes")) -> Diabetes | F10: yes | G10: No | H10: Yes | I10: 1 | J10: =IF(I10="No major surgery",0,I10) -> 1 | K10: yes | L10: =IF(K10="?","No",K10) -> yes | M10: Diabetes status
A11: Id10 | B11: 38.06 | C11: =IF(B11<18.5,"Underweight",IF(B11<25,"Normal weight", IF(B11<30,"Overweight","Obesity"))) -> Obesity | D11: 10.79 | E11: =IF(D11<5.7,"Normal",IF(D11<6.5,"Pre-diabetes","Diabetes")) -> Diabetes | F11: No | G11: No | H11: No | I11: No major surgery | J11: =IF(I11="No major surgery",0,I11) -> 0 | K11: yes | L11: =IF(K11="?","No",K11) -> yes | M11: <5.7 | N11: normal
A12: Id11 | B12: 37.7 | C12: =IF(B12<18.5,"Underweight",IF(B12<25,"Normal weight", IF(B12<30,"Overweight","Obesity"))) -> Obesity | D12: 5.96 | E12: =IF(D12<5.7,"Normal",IF(D12<6.5,"Pre-diabetes","Diabetes")) -> Pre-diabetes | F12: yes | G12: No | H12: No | I12: 2 | J12: =IF(I12="No major surgery",0,I12) -> 2 | K12: yes | L12: =IF(K12="?","No",K12) -> yes | M12: >5.7<=6.4 | N12: Pre diabetes
A13: Id12 | B13: 42.13 | C13: =IF(B13<18.5,"Underweight",IF(B13<25,"Normal weight", IF(B13<30,"Overweight","Obesity"))) -> Obesity | D13: 11.9 | E13: =IF(D13<5.7,"Normal",IF(D13<6.5,"Pre-diabetes","Diabetes")) -> Diabetes | F13: No | G13: No | H13: No | I13: No major surgery | J13: =IF(I13="No major surgery",0,I13) -> 0 | K13: yes | L13: =IF(K13="?","No",K13) -> yes | M13: >6.5 | N13: Diabetes
A14: Id13 | B14: 40.92 | C14: =IF(B14<18.5,"Underweight",IF(B14<25,"Normal weight", IF(B14<30,"Overweight","Obesity"))) -> Obesity | D14: 8.41 | E14: =IF(D14<5.7,"Normal",IF(D14<6.5,"Pre-diabetes","Diabetes")) -> Diabetes | F14: No | G14: No | H14: No | I14: No major surgery | J14: =IF(I14="No major surgery",0,I14) -> 0 | K14: yes | L14: =IF(K14="?","No",K14) -> yes
A15: Id14 | B15: 40.565 | C15: =IF(B15<18.5,"Underweight",IF(B15<25,"Normal weight", IF(B15<30,"Overweight","Obesity"))) -> Obesity | D15: 7.02 | E15: =IF(D15<5.7,"Normal",IF(D15<6.5,"Pre-diabetes","Diabetes")) -> Diabetes | F15: No | G15: No | H15: No | I15: No major surgery | J15: =IF(I15="No major surgery",0,I15) -> 0 | K15: yes | L15: =IF(K15="?","No",K15) -> yes
A16: Id15 | B16: 36.385 | C16: =IF(B16<18.5,"Underweight",IF(B16<25,"Normal weight", IF(B16<30,"Overweight","Obesity"))) -> Obesity | D16: 7.59 | E16: =IF(D16<5.7,"Normal",IF(D16<6.5,"Pre-diabetes","Diabetes")) -> Diabetes | F16: yes | G16: No | H16: No | I16: 2 | J16: =IF(I16="No major surgery",0,I16) -> 2 | K16: yes | L16: =IF(K16="?","No",K16) -> yes
A17: Id16 | B17: 39.9 | C17: =IF(B17<18.5,"Underweight",IF(B17<25,"Normal weight", IF(B17<30,"Overweight","Obesity"))) -> Obesity | D17: 11.32 | E17: =IF(D17<5.7,"Normal",IF(D17<6.5,"Pre-diabetes","Diabetes")) -> Diabetes | F17: No | G17: No | H17: No | I17: No major surgery | J17: =IF(I17="No major surgery",0,I17) -> 0 | K17: yes | L17: =IF(K17="?","No",K17) -> yes
A18: Id17 | B18: 33.8 | C18: =IF(B18<18.5,"Underweight",IF(B18<25,"Normal weight", IF(B18<30,"Overweight","Obesity"))) -> Obesity | D18: 7.67 | E18: =IF(D18<5.7,"Normal",IF(D18<6.5,"Pre-diabetes","Diabetes")) -> Diabetes | F18: No | G18: No | H18: No | I18: 3 | J18: =IF(I18="No major surgery",0,I18) -> 3 | K18: yes | L18: =IF(K18="?","No",K18) -> yes
A19: Id18 | B19: 36.765 | C19: =IF(B19<18.5,"Underweight",IF(B19<25,"Normal weight", IF(B19<30,"Overweight","Obesity"))) -> Obesity | D19: 7.29 | E19: =IF(D19<5.7,"Normal",IF(D19<6.5,"Pre-diabetes","Diabetes")) -> Diabetes | F19: yes | G19: No | H19: Yes | I19: 1 | J19: =IF(I19="No major surgery",0,I19) -> 1 | K19: yes | L19: =IF(K19="?","No",K19) -> yes
A20: Id19 | B20: 36.955 | C20: =IF(B20<18.5,"Underweight",IF(B20<25,"Normal weight", IF(B20<30,"Overweight","Obesity"))) -> Obesity | D20: 4.72 | E20: =IF(D20<5.7,"Normal",IF(D20<6.5,"Pre-diabetes","Diabetes")) -> Normal | F20: yes | G20: No | H20: No | I20: 1 | J20: =IF(I20="No major surgery",0,I20) -> 1 | K20: yes | L20: =IF(K20="?","No",K20) -> yes
A21: Id20 | B21: 42.9 | C21: =IF(B21<18.5,"Underweight",IF(B21<25,"Normal weight", IF(B21<30,"Overweight","Obesity"))) -> Obesity | D21: 11.41 | E21: =IF(D21<5.7,"Normal",IF(D21<6.5,"Pre-diabetes","Diabetes")) -> Diabetes | F21: No | G21: No | H21: No | I21: No major surgery | J21: =IF(I21="No major surgery",0,I21) -> 0 | K21: yes | L21: =IF(K21="?","No",K21) -> yes
A22: Id21 | B22: 36.3 | C22: =IF(B22<18.5,"Underweight",IF(B22<25,"Normal weight", IF(B22<30,"Overweight","Obesity"))) -> Obesity | D22: 11.5 | E22: =IF(D22<5.7,"Normal",IF(D22<6.5,"Pre-diabetes","Diabetes")) -> Diabetes | F22: yes | G22: No | H22: No | I22: 2 | J22: =IF(I22="No major surgery",0,I22) -> 2 | K22: yes | L22: =IF(K22="?","No",K22) -> yes
A23: Id22 | B23: 32.2 | C23: =IF(B23<18.5,"Underweight",IF(B23<25,"Normal weight", IF(B23<30,"Overweight","Obesity"))) -> Obesity | D23: 6.22 | E23: =IF(D23<5.7,"Normal",IF(D23<6.5,"Pre-diabetes","Diabetes")) -> Pre-diabetes | F23: yes | G23: No | H23: No | I23: 2 | J23: =IF(I23="No major surgery",0,I23) -> 2 | K23: yes | L23: =IF(K23="?","No",K23) -> yes
A24: Id23 | B24: 31.3 | C24: =IF(B24<18.5,"Underweight",IF(B24<25,"Normal weight", IF(B24<30,"Overweight","Obesity"))) -> Obesity | D24: 11.38 | E24: =IF(D24<5.7,"Normal",IF(D24<6.5,"Pre-diabetes","Diabetes")) -> Diabetes | F24: No | G24: No | H24: No | I24: 3 | J24: =IF(I24="No major surgery",0,I24) -> 3 | K24: yes | L24: =IF(K24="?","No",K24) -> yes
A25: Id24 | B25: 41.8 | C25: =IF(B25<18.5,"Underweight",IF(B25<25,"Normal weight", IF(B25<30,"Overweight","Obesity"))) -> Obesity | D25: 7.89 | E25: =IF(D25<5.7,"Normal",IF(D25<6.5,"Pre-diabetes","Diabetes")) -> Diabetes | F25: yes | G25: No | H25: No | I25: 2 | J25: =IF(I25="No major surgery",0,I25) -> 2 | K25: yes | L25: =IF(K25="?","No",K25) -> yes
A26: Id25 | B26: 35.09 | C26: =IF(B26<18.5,"Underweight",IF(B26<25,"Normal weight", IF(B26<30,"Overweight","Obesity"))) -> Obesity | D26: 4.38 | E26: =IF(D26<5.7,"Normal",IF(D26<6.5,"Pre-diabetes","Diabetes")) -> Normal | F26: yes | G26: No | H26: No | I26: 2 | J26: =IF(I26="No major surgery",0,I26) -> 2 | K26: yes | L26: =IF(K26="?","No",K26) -> yes
A27: Id26 | B27: 33.88 | C27: =IF(B27<18.5,"Underweight",IF(B27<25,"Normal weight", IF(B27<30,"Overweight","Obesity"))) -> Obesity | D27: 7.01 | E27: =IF(D27<5.7,"Normal",IF(D27<6.5,"Pre-diabetes","Diabetes")) -> Diabetes | F27: No | G27: No | H27: No | I27: 3 | J27: =IF(I27="No major surgery",0,I27) -> 3 | K27: yes | L27: =IF(K27="?","No",K27) -> yes
A28: Id27 | B28: 30.875 | C28: =IF(B28<18.5,"Underweight",IF(B28<25,"Normal weight", IF(B28<30,"Overweight","Obesity"))) -> Obesity | D28: 11.88 | E28: =IF(D28<5.7,"Normal",IF(D28<6.5,"Pre-diabetes","Diabetes")) -> Diabetes | F28: No | G28: No | H28: No | I28: No major surgery | J28: =IF(I28="No major surgery",0,I28) -> 0 | K28: yes | L28: =IF(K28="?","No",K28) -> yes
A29: Id28 | B29: 36.86 | C29: =IF(B29<18.5,"Underweight",IF(B29<25,"Normal weight", IF(B29<30,"Overweight","Obesity"))) -> Obesity | D29: 5.19 | E29: =IF(D29<5.7,"Normal",IF(D29<6.5,"Pre-diabetes","Diabetes")) -> Normal | F29: yes | G29: No | H29: Yes | I29: 1 | J29: =IF(I29="No major surgery",0,I29) -> 1 | K29: yes | L29: =IF(K29="?","No",K29) -> yes
A30: Id29 | B30: 35.86 | C30: =IF(B30<18.5,"Underweight",IF(B30<25,"Normal weight", IF(B30<30,"Overweight","Obesity"))) -> Obesity | D30: 6.74 | E30: =IF(D30<5.7,"Normal",IF(D30<6.5,"Pre-diabetes","Diabetes")) -> Diabetes | F30: yes | G30: No | H30: No | I30: 2 | J30: =IF(I30="No major surgery",0,I30) -> 2 | K30: yes | L30: =IF(K30="?","No",K30) -> yes
A31: Id30 | B31: 37.05 | C31: =IF(B31<18.5,"Underweight",IF(B31<25,"Normal weight", IF(B31<30,"Overweight","Obesity"))) -> Obesity | D31: 8.44 | E31: =IF(D31<5.7,"Normal",IF(D31<6.5,"Pre-diabetes","Diabetes")) -> Diabetes | F31: No | G31: No | H31: No | I31: No major surgery | J31: =IF(I31="No major surgery",0,I31) -> 0 | K31: yes | L31: =IF(K31="?","No",K31) -> yes
A32: Id31 | B32: 43.89 | C32: =IF(B32<18.5,"Underweight",IF(B32<25,"Normal weight", IF(B32<30,"Overweight","Obesity"))) -> Obesity | D32: 8.71 | E32: =IF(D32<5.7,"Normal",IF(D32<6.5,"Pre-diabetes","Diabetes")) -> Diabetes | F32: No | G32: No | H32: No | I32: No major surgery | J32: =IF(I32="No major surgery",0,I32) -> 0 | K32: yes | L32: =IF(K32="?","No",K32) -> yes
A33: Id32 | B33: 42.35 | C33: =IF(B33<18.5,"Underweight",IF(B33<25,"Normal weight", IF(B33<30,"Overweight","Obesity"))) -> Obesity | D33: 5.08 | E33: =IF(D33<5.7,"Normal",IF(D33<6.5,"Pre-diabetes","Diabetes")) -> Normal | F33: yes | G33: No | H33: No | I33: No major surgery | J33: =IF(I33="No major surgery",0,I33) -> 0 | K33: yes | L33: =IF(K33="?","No",K33) -> yes
A34: Id33 | B34: 31.35 | C34: =IF(B34<18.5,"Underweight",IF(B34<25,"Normal weight", IF(B34<30,"Overweight","Obesity"))) -> Obesity | D34: 6.86 | E34: =IF(D34<5.7,"Normal",IF(D34<6.5,"Pre-diabetes","Diabetes")) -> Diabetes | F34: No | G34: No | H34: No | I34: No major surgery | J34: =IF(I34="No major surgery",0,I34) -> 0 | K34: yes | L34: =IF(K34="?","No",K34) -> yes
A35: Id34 | B35: 47.6 | C35: =IF(B35<18.5,"Underweight",IF(B35<25,"Normal weight", IF(B35<30,"Overweight","Obesity"))) -> Obesity | D35: 5.95 | E35: =IF(D35<5.7,"Normal",IF(D35<6.5,"Pre-diabetes","Diabetes")) -> Pre-diabetes | F35: yes | G35: No | H35: No | I35: No major surgery | J35: =IF(I35="No major surgery",0,I35) -> 0 | K35: yes | L35: =IF(K35="?","No",K35) -> yes
A36: Id35 | B36: 46.2 | C36: =IF(B36<18.5,"Underweight",IF(B36<25,"Normal weight", IF(B36<30,"Overweight","Obesity"))) -> Obesity | D36: 6.09 | E36: =IF(D36<5.7,"Normal",IF(D36<6.5,"Pre-diabetes","Diabetes")) -> Pre-diabetes | F36: No | G36: No | H36: Yes | I36: 1 | J36: =IF(I36="No major surgery",0,I36) -> 1 | K36: yes | L36: =IF(K36="?","No",K36) -> yes
A37: Id36 | B37: 32.015 | C37: =IF(B37<18.5,"Underweight",IF(B37<25,"Normal weight", IF(B37<30,"Overweight","Obesity"))) -> Obesity | D37: 11.75 | E37: =IF(D37<5.7,"Normal",IF(D37<6.5,"Pre-diabetes","Diabetes")) -> Diabetes | F37: No | G37: No | H37: No | I37: No major surgery | J37: =IF(I37="No major surgery",0,I37) -> 0 | K37: yes | L37: =IF(K37="?","No",K37) -> yes
A38: Id37 | B38: 40.565 | C38: =IF(B38<18.5,"Underweight",IF(B38<25,"Normal weight", IF(B38<30,"Overweight","Obesity"))) -> Obesity | D38: 7.37 | E38: =IF(D38<5.7,"Normal",IF(D38<6.5,"Pre-diabetes","Diabetes")) -> Diabetes | F38: No | G38: No | H38: No | I38: No major surgery | J38: =IF(I38="No major surgery",0,I38) -> 0 | K38: yes | L38: =IF(K38="?","No",K38) -> yes
A39: Id38 | B39: 32.45 | C39: =IF(B39<18.5,"Underweight",IF(B39<25,"Normal weight", IF(B39<30,"Overweight","Obesity"))) -> Obesity | D39: 11.91 | E39: =IF(D39<5.7,"Normal",IF(D39<6.5,"Pre-diabetes","Diabetes")) -> Diabetes | F39: No | G39: No | H39: No | I39: No major surgery | J39: =IF(I39="No major surgery",0,I39) -> 0 | K39: yes | L39: =IF(K39="?","No",K39) -> yes
A40: Id39 | B40: 34.96 | C40: =IF(B40<18.5,"Underweight",IF(B40<25,"Normal weight", IF(B40<30,"Overweight","Obesity"))) -> Obesity | D40: 6.52 | E40: =IF(D40<5.7,"Normal",IF(D40<6.5,"Pre-diabetes","Diabetes")) -> Diabetes | F40: No | G40: No | H40: No | I40: No major surgery | J40: =IF(I40="No major surgery",0,I40) -> 0 | K40: yes | L40: =IF(K40="?","No",K40) -> yes
...

Sheet Hospitalisation Details
A1: Customer ID | B1: ID imputed | C1: year | D1: Year Imputed | E1: month | F1: Month imputed | G1: Date | H1: Date of Birth | I1: DOB value paste | J1: Age | K1: Children | L1: Charges | M1: Hospital tier | N1: Encoding | O1: Hospital Tier imputed | P1: City tier | Q1: Encoding | R1: City tier | S1: State ID | T1: State ID Imputed
A2: Id2335 | B2: =IF(A2="?", "Unknown",A2) -> Id2335 | C2: 1992 | D2: =IF(C2="?",ROUND(AVERAGE($C$2:$C$2344),0),C2) -> 1992 | E2: Jul | F2: =IF(E2="?","Sep",E2) -> Jul | G2: 9 | H2: =CONCATENATE(G2,"-",F2,"-",D2) -> 9-Jul-1992 | I2: 33794 | J2: =DATEDIF(I2,"8-6-2023","Y") -> 30 | K2: 0 | L2: 563.84 | M2: tier - 2 | N2: =MATCH(M2,$M$2:$M$2344,0) -> 1 | O2: =IF(M2="?",INDEX($M$2:$M$2344,MODE($N$2:$N$2344)),M2) -> tier - 2 | P2: tier - 3 | Q2: =MATCH(P2,$P$2:$P$2344,0) -> 1 | R2: =IF(P2="?",INDEX($P$2:$P$2344,MODE($Q$2:$Q$2344)),P2) -> tier - 3 | S2: R1013 | T2: =IF(S2="?","Unknown",S2) -> R1013
A3: Id2334 | B3: =IF(A3="?", "Unknown",A3) -> Id2334 | C3: 1992 | D3: =IF(C3="?",ROUND(AVERAGE($C$2:$C$2344),0),C3) -> 1992 | E3: Nov | F3: =IF(E3="?","Sep",E3) -> Nov | G3: 30 | H3: =CONCATENATE(G3,"-",F3,"-",D3) -> 30-Nov-1992 | I3: 33938 | J3: =DATEDIF(I3,"8-6-2023","Y") -> 30 | K3: 0 | L3: 570.62 | M3: tier - 2 | N3: =MATCH(M3,$M$2:$M$2344,0) -> 1 | O3: =IF(M3="?",INDEX($M$2:$M$2344,MODE($N$2:$N$2344)),M3) -> tier - 2 | P3: tier - 1 | Q3: =MATCH(P3,$P$2:$P$2344,0) -> 2 | R3: =IF(P3="?",INDEX($P$2:$P$2344,MODE($Q$2:$Q$2344)),P3) -> tier - 1 | S3: R1013 | T3: =IF(S3="?","Unknown",S3) -> R1013
A4: Id2333 | B4: =IF(A4="?", "Unknown",A4) -> Id2333 | C4: 1993 | D4: =IF(C4="?",ROUND(AVERAGE($C$2:$C$2344),0),C4) -> 1993 | E4: Jun | F4: =IF(E4="?","Sep",E4) -> Jun | G4: 30 | H4: =CONCATENATE(G4,"-",F4,"-",D4) -> 30-Jun-1993 | I4: 34150 | J4: =DATEDIF(I4,"8-6-2023","Y") -> 29 | K4: 0 | L4: 600 | M4: tier - 2 | N4: =MATCH(M4,$M$2:$M$2344,0) -> 1 | O4: =IF(M4="?",INDEX($M$2:$M$2344,MODE($N$2:$N$2344)),M4) -> tier - 2 | P4: tier - 1 | Q4: =MATCH(P4,$P$2:$P$2344,0) -> 2 | R4: =IF(P4="?",INDEX($P$2:$P$2344,MODE($Q$2:$Q$2344)),P4) -> tier - 1 | S4: R1013 | T4: =IF(S4="?","Unknown",S4) -> R1013 | U4: number of missing values marked with '?' | V4: =COUNTIF(A1:S2344,"?") -> 15
A5: Id2332 | B5: =IF(A5="?", "Unknown",A5) -> Id2332 | C5: 1992 | D5: =IF(C5="?",ROUND(AVERAGE($C$2:$C$2344),0),C5) -> 1992 | E5: Sep | F5: =IF(E5="?","Sep",E5) -> Sep | G5: 13 | H5: =CONCATENATE(G5,"-",F5,"-",D5) -> 13-Sep-1992 | I5: 33860 | J5: =DATEDIF(I5,"8-6-2023","Y") -> 30 | K5: 0 | L5: 604.54 | M5: tier - 3 | N5: =MATCH(M5,$M$2:$M$2344,0) -> 4 | O5: =IF(M5="?",INDEX($M$2:$M$2344,MODE($N$2:$N$2344)),M5) -> tier - 3 | P5: tier - 3 | Q5: =MATCH(P5,$P$2:$P$2344,0) -> 1 | R5: =IF(P5="?",INDEX($P$2:$P$2344,MODE($Q$2:$Q$2344)),P5) -> tier - 3 | S5: R1013 | T5: =IF(S5="?","Unknown",S5) -> R1013
A6: Id2331 | B6: =IF(A6="?", "Unknown",A6) -> Id2331 | C6: 1998 | D6: =IF(C6="?",ROUND(AVERAGE($C$2:$C$2344),0),C6) -> 1998 | E6: Jul | F6: =IF(E6="?","Sep",E6) -> Jul | G6: 27 | H6: =CONCATENATE(G6,"-",F6,"-",D6) -> 27-Jul-1998 | I6: 36003 | J6: =DATEDIF(I6,"8-6-2023","Y") -> 24 | K6: 0 | L6: 637.26 | M6: tier - 3 | N6: =MATCH(M6,$M$2:$M$2344,0) -> 4 | O6: =IF(M6="?",INDEX($M$2:$M$2344,MODE($N$2:$N$2344)),M6) -> tier - 3 | P6: tier - 3 | Q6: =MATCH(P6,$P$2:$P$2344,0) -> 1 | R6: =IF(P6="?",INDEX($P$2:$P$2344,MODE($Q$2:$Q$2344)),P6) -> tier - 3 | S6: R1013 | T6: =IF(S6="?","Unknown",S6) -> R1013
A7: Id2330 | B7: =IF(A7="?", "Unknown",A7) -> Id2330 | C7: 2001 | D7: =IF(C7="?",ROUND(AVERAGE($C$2:$C$2344),0),C7) -> 2001 | E7: Nov | F7: =IF(E7="?","Sep",E7) -> Nov | G7: 20 | H7: =CONCATENATE(G7,"-",F7,"-",D7) -> 20-Nov-2001 | I7: 37215 | J7: =DATEDIF(I7,"8-6-2023","Y") -> 21 | K7: 0 | L7: 646.14 | M7: tier - 3 | N7: =MATCH(M7,$M$2:$M$2344,0) -> 4 | O7: =IF(M7="?",INDEX($M$2:$M$2344,MODE($N$2:$N$2344)),M7) -> tier - 3 | P7: tier - 3 | Q7: =MATCH(P7,$P$2:$P$2344,0) -> 1 | R7: =IF(P7="?",INDEX($P$2:$P$2344,MODE($Q$2:$Q$2344)),P7) -> tier - 3 | S7: R1012 | T7: =IF(S7="?","Unknown",S7) -> R1012 | X7: tier 1 | Y7: =COUNTIF($P$2:$P$2344,"tier - 1") -> 734
A8: Id2329 | B8: =IF(A8="?", "Unknown",A8) -> Id2329 | C8: 1993 | D8: =IF(C8="?",ROUND(AVERAGE($C$2:$C$2344),0),C8) -> 1993 | E8: Jun | F8: =IF(E8="?","Sep",E8) -> Jun | G8: 1 | H8: =CONCATENATE(G8,"-",F8,"-",D8) -> 1-Jun-1993 | I8: 34121 | J8: =DATEDIF(I8,"8-6-2023","Y") -> 30 | K8: 0 | L8: 650 | M8: tier - 3 | N8: =MATCH(M8,$M$2:$M$2344,0) -> 4 | O8: =IF(M8="?",INDEX($M$2:$M$2344,MODE($N$2:$N$2344)),M8) -> tier - 3 | P8: tier - 3 | Q8: =MATCH(P8,$P$2:$P$2344,0) -> 1 | R8: =IF(P8="?",INDEX($P$2:$P$2344,MODE($Q$2:$Q$2344)),P8) -> tier - 3 | S8: R1013 | T8: =IF(S8="?","Unknown",S8) -> R1013 | X8: tier 2 | Y8: =COUNTIF($P$2:$P$2344,"tier - 2") -> 812
A9: Id2328 | B9: =IF(A9="?", "Unknown",A9) -> Id2328 | C9: 1995 | D9: =IF(C9="?",ROUND(AVERAGE($C$2:$C$2344),0),C9) -> 1995 | E9: Jul | F9: =IF(E9="?","Sep",E9) -> Jul | G9: 4 | H9: =CONCATENATE(G9,"-",F9,"-",D9) -> 4-Jul-1995 | I9: 34884 | J9: =DATEDIF(I9,"8-6-2023","Y") -> 27 | K9: 0 | L9: 650 | M9: tier - 3 | N9: =MATCH(M9,$M$2:$M$2344,0) -> 4 | O9: =IF(M9="?",INDEX($M$2:$M$2344,MODE($N$2:$N$2344)),M9) -> tier - 3 | P9: tier - 3 | Q9: =MATCH(P9,$P$2:$P$2344,0) -> 1 | R9: =IF(P9="?",INDEX($P$2:$P$2344,MODE($Q$2:$Q$2344)),P9) -> tier - 3 | S9: R1013 | T9: =IF(S9="?","Unknown",S9) -> R1013 | X9: tier 3 | Y9: =COUNTIF($P$2:$P$2344,"tier - 3") -> 796
A10: Id2327 | B10: =IF(A10="?", "Unknown",A10) -> Id2327 | C10: 2002 | D10: =IF(C10="?",ROUND(AVERAGE($C$2:$C$2344),0),C10) -> 2002 | E10: Nov | F10: =IF(E10="?","Sep",E10) -> Nov | G10: 29 | H10: =CONCATENATE(G10,"-",F10,"-",D10) -> 29-Nov-2002 | I10: 37589 | J10: =DATEDIF(I10,"8-6-2023","Y") -> 20 | K10: 0 | L10: 668 | M10: tier - 3 | N10: =MATCH(M10,$M$2:$M$2344,0) -> 4 | O10: =IF(M10="?",INDEX($M$2:$M$2344,MODE($N$2:$N$2344)),M10) -> tier - 3 | P10: tier - 2 | Q10: =MATCH(P10,$P$2:$P$2344,0) -> 9 | R10: =IF(P10="?",INDEX($P$2:$P$2344,MODE($Q$2:$Q$2344)),P10) -> tier - 2 | S10: R1012 | T10: =IF(S10="?","Unknown",S10) -> R1012
A11: Id2326 | B11: =IF(A11="?", "Unknown",A11) -> Id2326 | C11: 1997 | D11: =IF(C11="?",ROUND(AVERAGE($C$2:$C$2344),0),C11) -> 1997 | E11: Nov | F11: =IF(E11="?","Sep",E11) -> Nov | G11: 9 | H11: =CONCATENATE(G11,"-",F11,"-",D11) -> 9-Nov-1997 | I11: 35743 | J11: =DATEDIF(I11,"8-6-2023","Y") -> 25 | K11: 0 | L11: 670 | M11: tier - 3 | N11: =MATCH(M11,$M$2:$M$2344,0) -> 4 | O11: =IF(M11="?",INDEX($M$2:$M$2344,MODE($N$2:$N$2344)),M11) -> tier - 3 | P11: tier - 3 | Q11: =MATCH(P11,$P$2:$P$2344,0) -> 1 | R11: =IF(P11="?",INDEX($P$2:$P$2344,MODE($Q$2:$Q$2344)),P11) -> tier - 3 | S11: R1013 | T11: =IF(S11="?","Unknown",S11) -> R1013
A12: Id2325 | B12: =IF(A12="?", "Unknown",A12) -> Id2325 | C12: 2001 | D12: =IF(C12="?",ROUND(AVERAGE($C$2:$C$2344),0),C12) -> 2001 | E12: Sep | F12: =IF(E12="?","Sep",E12) -> Sep | G12: 12 | H12: =CONCATENATE(G12,"-",F12,"-",D12) -> 12-Sep-2001 | I12: 37146 | J12: =DATEDIF(I12,"8-6-2023","Y") -> 21 | K12: 0 | L12: 687.54 | M12: tier - 3 | N12: =MATCH(M12,$M$2:$M$2344,0) -> 4 | O12: =IF(M12="?",INDEX($M$2:$M$2344,MODE($N$2:$N$2344)),M12) -> tier - 3 | P12: tier - 2 | Q12: =MATCH(P12,$P$2:$P$2344,0) -> 9 | R12: =IF(P12="?",INDEX($P$2:$P$2344,MODE($Q$2:$Q$2344)),P12) -> tier - 2 | S12: R1013 | T12: =IF(S12="?","Unknown",S12) -> R1013
A13: Id2324 | B13: =IF(A13="?", "Unknown",A13) -> Id2324 | C13: 1999 | D13: =IF(C13="?",ROUND(AVERAGE($C$2:$C$2344),0),C13) -> 1999 | E13: Dec | F13: =IF(E13="?","Sep",E13) -> Dec | G13: 26 | H13: =CONCATENATE(G13,"-",F13,"-",D13) -> 26-Dec-1999 | I13: 36520 | J13: =DATEDIF(I13,"8-6-2023","Y") -> 23 | K13: 0 | L13: 700 | M13: ? | N13: =MATCH(M13,$M$2:$M$2344,0) -> 12 | O13: =IF(M13="?",INDEX($M$2:$M$2344,MODE($N$2:$N$2344)),M13) -> tier - 2 | P13: tier - 3 | Q13: =MATCH(P13,$P$2:$P$2344,0) -> 1 | R13: =IF(P13="?",INDEX($P$2:$P$2344,MODE($Q$2:$Q$2344)),P13) -> tier - 3 | S13: R1013 | T13: =IF(S13="?","Unknown",S13) -> R1013
A14: Id2323 | B14: =IF(A14="?", "Unknown",A14) -> Id2323 | C14: 1999 | D14: =IF(C14="?",ROUND(AVERAGE($C$2:$C$2344),0),C14) -> 1999 | E14: Dec | F14: =IF(E14="?","Sep",E14) -> Dec | G14: 14 | H14: =CONCATENATE(G14,"-",F14,"-",D14) -> 14-Dec-1999 | I14: 36508 | J14: =DATEDIF(I14,"8-6-2023","Y") -> 23 | K14: 0 | L14: 722.99 | M14: tier - 3 | N14: =MATCH(M14,$M$2:$M$2344,0) -> 4 | O14: =IF(M14="?",INDEX($M$2:$M$2344,MODE($N$2:$N$2344)),M14) -> tier - 3 | P14: tier - 1 | Q14: =MATCH(P14,$P$2:$P$2344,0) -> 2 | R14: =IF(P14="?",INDEX($P$2:$P$2344,MODE($Q$2:$Q$2344)),P14) -> tier - 1 | S14: R1013 | T14: =IF(S14="?","Unknown",S14) -> R1013
A15: Id2322 | B15: =IF(A15="?", "Unknown",A15) -> Id2322 | C15: 2002 | D15: =IF(C15="?",ROUND(AVERAGE($C$2:$C$2344),0),C15) -> 2002 | E15: ? | F15: =IF(E15="?","Sep",E15) -> Sep | G15: 19 | H15: =CONCATENATE(G15,"-",F15,"-",D15) -> 19-Sep-2002 | I15: 37518 | J15: =DATEDIF(I15,"8-6-2023","Y") -> 20 | K15: 0 | L15: 750 | M15: tier - 3 | N15: =MATCH(M15,$M$2:$M$2344,0) -> 4 | O15: =IF(M15="?",INDEX($M$2:$M$2344,MODE($N$2:$N$2344)),M15) -> tier - 3 | P15: tier - 1 | Q15: =MATCH(P15,$P$2:$P$2344,0) -> 2 | R15: =IF(P15="?",INDEX($P$2:$P$2344,MODE($Q$2:$Q$2344)),P15) -> tier - 1 | S15: R1012 | T15: =IF(S15="?","Unknown",S15) -> R1012
A16: Id2321 | B16: =IF(A16="?", "Unknown",A16) -> Id2321 | C16: 1993 | D16: =IF(C16="?",ROUND(AVERAGE($C$2:$C$2344),0),C16) -> 1993 | E16: Aug | F16: =IF(E16="?","Sep",E16) -> Aug | G16: 9 | H16: =CONCATENATE(G16,"-",F16,"-",D16) -> 9-Aug-1993 | I16: 34190 | J16: =DATEDIF(I16,"8-6-2023","Y") -> 29 | K16: 0 | L16: 760 | M16: tier - 3 | N16: =MATCH(M16,$M$2:$M$2344,0) -> 4 | O16: =IF(M16="?",INDEX($M$2:$M$2344,MODE($N$2:$N$2344)),M16) -> tier - 3 | P16: tier - 1 | Q16: =MATCH(P16,$P$2:$P$2344,0) -> 2 | R16: =IF(P16="?",INDEX($P$2:$P$2344,MODE($Q$2:$Q$2344)),P16) -> tier - 1 | S16: R1013 | T16: =IF(S16="?","Unknown",S16) -> R1013
A17: Id2320 | B17: =IF(A17="?", "Unknown",A17) -> Id2320 | C17: 1996 | D17: =IF(C17="?",ROUND(AVERAGE($C$2:$C$2344),0),C17) -> 1996 | E17: Oct | F17: =IF(E17="?","Sep",E17) -> Oct | G17: 22 | H17: =CONCATENATE(G17,"-",F17,"-",D17) -> 22-Oct-1996 | I17: 35360 | J17: =DATEDIF(I17,"8-6-2023","Y") -> 26 | K17: 0 | L17: 760 | M17: tier - 3 | N17: =MATCH(M17,$M$2:$M$2344,0) -> 4 | O17: =IF(M17="?",INDEX($M$2:$M$2344,MODE($N$2:$N$2344)),M17) -> tier - 3 | P17: tier - 3 | Q17: =MATCH(P17,$P$2:$P$2344,0) -> 1 | R17: =IF(P17="?",INDEX($P$2:$P$2344,MODE($Q$2:$Q$2344)),P17) -> tier - 3 | S17: R1013 | T17: =IF(S17="?","Unknown",S17) -> R1013
A18: Id2319 | B18: =IF(A18="?", "Unknown",A18) -> Id2319 | C18: 1993 | D18: =IF(C18="?",ROUND(AVERAGE($C$2:$C$2344),0),C18) -> 1993 | E18: Jun | F18: =IF(E18="?","Sep",E18) -> Jun | G18: 28 | H18: =CONCATENATE(G18,"-",F18,"-",D18) -> 28-Jun-1993 | I18: 34148 | J18: =DATEDIF(I18,"8-6-2023","Y") -> 29 | K18: 0 | L18: 770 | M18: tier - 3 | N18: =MATCH(M18,$M$2:$M$2344,0) -> 4 | O18: =IF(M18="?",INDEX($M$2:$M$2344,MODE($N$2:$N$2344)),M18) -> tier - 3 | P18: tier - 3 | Q18: =MATCH(P18,$P$2:$P$2344,0) -> 1 | R18: =IF(P18="?",INDEX($P$2:$P$2344,MODE($Q$2:$Q$2344)),P18) -> tier - 3 | S18: R1013 | T18: =IF(S18="?","Unknown",S18) -> R1013
A19: Id2318 | B19: =IF(A19="?", "Unknown",A19) -> Id2318 | C19: 1996 | D19: =IF(C19="?",ROUND(AVERAGE($C$2:$C$2344),0),C19) -> 1996 | E19: ? | F19: =IF(E19="?","Sep",E19) -> Sep | G19: 18 | H19: =CONCATENATE(G19,"-",F19,"-",D19) -> 18-Sep-1996 | I19: 35326 | J19: =DATEDIF(I19,"8-6-2023","Y") -> 26 | K19: 0 | L19: 770.38 | M19: tier - 3 | N19: =MATCH(M19,$M$2:$M$2344,0) -> 4 | O19: =IF(M19="?",INDEX($M$2:$M$2344,MODE($N$2:$N$2344)),M19) -> tier - 3 | P19: ? | Q19: =MATCH(P19,$P$2:$P$2344,0) -> 18 | R19: =IF(P19="?",INDEX($P$2:$P$2344,MODE($Q$2:$Q$2344)),P19) -> tier - 2 | S19: R1012 | T19: =IF(S19="?","Unknown",S19) -> R1012
A20: Id2317 | B20: =IF(A20="?", "Unknown",A20) -> Id2317 | C20: 1995 | D20: =IF(C20="?",ROUND(AVERAGE($C$2:$C$2344),0),C20) -> 1995 | E20: Dec | F20: =IF(E20="?","Sep",E20) -> Dec | G20: 7 | H20: =CONCATENATE(G20,"-",F20,"-",D20) -> 7-Dec-1995 | I20: 35040 | J20: =DATEDIF(I20,"8-6-2023","Y") -> 27 | K20: 0 | L20: 773.54 | M20: tier - 3 | N20: =MATCH(M20,$M$2:$M$2344,0) -> 4 | O20: =IF(M20="?",INDEX($M$2:$M$2344,MODE($N$2:$N$2344)),M20) -> tier - 3 | P20: tier - 2 | Q20: =MATCH(P20,$P$2:$P$2344,0) -> 9 | R20: =IF(P20="?",INDEX($P$2:$P$2344,MODE($Q$2:$Q$2344)),P20) -> tier - 2 | S20: R1013 | T20: =IF(S20="?","Unknown",S20) -> R1013
A21: Id2316 | B21: =IF(A21="?", "Unknown",A21) -> Id2316 | C21: 2004 | D21: =IF(C21="?",ROUND(AVERAGE($C$2:$C$2344),0),C21) -> 2004 | E21: Oct | F21: =IF(E21="?","Sep",E21) -> Oct | G21: 7 | H21: =CONCATENATE(G21,"-",F21,"-",D21) -> 7-Oct-2004 | I21: 38267 | J21: =DATEDIF(I21,"8-6-2023","Y") -> 18 | K21: 0 | L21: 830.52 | M21: tier - 3 | N21: =MATCH(M21,$M$2:$M$2344,0) -> 4 | O21: =IF(M21="?",INDEX($M$2:$M$2344,MODE($N$2:$N$2344)),M21) -> tier - 3 | P21: tier - 2 | Q21: =MATCH(P21,$P$2:$P$2344,0) -> 9 | R21: =IF(P21="?",INDEX($P$2:$P$2344,MODE($Q$2:$Q$2344)),P21) -> tier - 2 | S21: R1011 | T21: =IF(S21="?","Unknown",S21) -> R1011
... A1050: Id1290 | B1050: =IF(A1050="?", "Unknown",A1050) -> Id1290 | C1050: 1977 | D1050: =IF(C1050="?",ROUND(AVERAGE($C$2:$C$2344),0),C1050) -> 1977 | E1050: Jul | F1050: =IF(E1050="?","Sep",E1050) -> Jul | G1050: 26 | H1050: =CONCATENATE(G1050,"-",F1050,"-",D1050) -> 26-Jul-1977 | I1050: 28332 | J1050: =DATEDIF(I1050,"8-6-2023","Y") -> 45 | K1050: 2 | L1050: 8527.53 | M1050: tier - 2 | N1050: =MATCH(M1050,$M$2:$M$2344,0) -> 1 | O1050: =IF(M1050="?",INDEX($M$2:$M$2344,MODE($N$2:$N$2344)),M1050) -> tier - 2 | P1050: tier - 2 | Q1050: =MATCH(P1050,$P$2:$P$2344,0) -> 9 | R1050: =IF(P1050="?",INDEX($P$2:$P$2344,MODE($Q$2:$Q$2344)),P1050) -> tier - 2 | S1050: R1013 | T1050: =IF(S1050="?","Unknown",S1050) -> R1013
A1051: Id1289 | B1051: =IF(A1051="?", "Unknown",A1051) -> Id1289 | C1051: ? | D1051: =IF(C1051="?",ROUND(AVERAGE($C$2:$C$2344),0),C1051) -> 1983 | E1051: Jul | F1051: =IF(E1051="?","Sep",E1051) -> Jul | G1051: 24 | H1051: =CONCATENATE(G1051,"-",F1051,"-",D1051) -> 24-Jul-1983 | I1051: 30521 | J1051: =DATEDIF(I1051,"8-6-2023","Y") -> 39 | K1051: 0 | L1051: 8534.67 | M1051: tier - 2 | N1051: =MATCH(M1051,$M$2:$M$2344,0) -> 1 | O1051: =IF(M1051="?",INDEX($M$2:$M$2344,MODE($N$2:$N$2344)),M1051) -> tier - 2 | P1051: tier - 3 | Q1051: =MATCH(P1051,$P$2:$P$2344,0) -> 1 | R1051: =IF(P1051="?",INDEX($P$2:$P$2344,MODE($Q$2:$Q$2344)),P1051) -> tier - 3 | S1051: R1024 | T1051: =IF(S1051="?","Unknown",S1051) -> R1024
A1052: Id1288 | B1052: =IF(A1052="?", "Unknown",A1052) -> Id1288 | C1052: 1981 | D1052: =IF(C1052="?",ROUND(AVERAGE($C$2:$C$2344),0),C1052) -> 1981 | E1052: Dec | F1052: =IF(E1052="?","Sep",E1052) -> Dec | G1052: 27 | H1052: =CONCATENATE(G1052,"-",F1052,"-",D1052) -> 27-Dec-1981 | I1052: 29947 | J1052: =DATEDIF(I1052,"8-6-2023","Y") -> 41 | K1052: 3 | L1052: 8538.29 | M1052: tier - 2 | N1052: =MATCH(M1052,$M$2:$M$2344,0) -> 1 | O1052: =IF(M1052="?",INDEX($M$2:$M$2344,MODE($N$2:$N$2344)),M1052) -> tier - 2 | P1052: tier - 3 | Q1052: =MATCH(P1052,$P$2:$P$2344,0) -> 1 | R1052: =IF(P1052="?",INDEX($P$2:$P$2344,MODE($Q$2:$Q$2344)),P1052) -> tier - 3 | S1052: R1024 | T1052: =IF(S1052="?","Unknown",S1052) -> R1024
A1053: Id1287 | B1053: =IF(A1053="?", "Unknown",A1053) -> Id1287 | C1053: 1975 | D1053: =IF(C1053="?",ROUND(AVERAGE($C$2:$C$2344),0),C1053) -> 1975 | E1053: Nov | F1053: =IF(E1053="?","Sep",E1053) -> Nov | G1053: 6 | H1053: =CONCATENATE(G1053,"-",F1053,"-",D1053) -> 6-Nov-1975 | I1053: 27704 | J1053: =DATEDIF(I1053,"8-6-2023","Y") -> 47 | K1053: 1 | L1053: 8539.67 | M1053: tier - 2 | N1053: =MATCH(M1053,$M$2:$M$2344,0) -> 1 | O1053: =IF(M1053="?",INDEX($M$2:$M$2344,MODE($N$2:$N$2344)),M1053) -> tier - 2 | P1053: tier - 3 | Q1053: =MATCH(P1053,$P$2:$P$2344,0) -> 1 | R1053: =IF(P1053="?",INDEX($P$2:$P$2344,MODE($Q$2:$Q$2344)),P1053) -> tier - 3 | S1053: R1011 | T1053: =IF(S1053="?","Unknown",S1053) -> R1011
A1054: Id1286 | B1054: =IF(A1054="?", "Unknown",A1054) -> Id1286 | C1054: ? | D1054: =IF(C1054="?",ROUND(AVERAGE($C$2:$C$2344),0),C1054) -> 1983 | E1054: Dec | F1054: =IF(E1054="?","Sep",E1054) -> Dec | G1054: 12 | H1054: =CONCATENATE(G1054,"-",F1054,"-",D1054) -> 12-Dec-1983 | I1054: 30662 | J1054: =DATEDIF(I1054,"8-6-2023","Y") -> 39 | K1054: 1 | L1054: 8547.69 | M1054: tier - 2 | N1054: =MATCH(M1054,$M$2:$M$2344,0) -> 1 | O1054: =IF(M1054="?",INDEX($M$2:$M$2344,MODE($N$2:$N$2344)),M1054) -> tier - 2 | P1054: tier - 1 | Q1054: =MATCH(P1054,$P$2:$P$2344,0) -> 2 | R1054: =IF(P1054="?",INDEX($P$2:$P$2344,MODE($Q$2:$Q$2344)),P1054) -> tier - 1 | S1054: R1013 | T1054: =IF(S1054="?","Unknown",S1054) -> R1013
A1055: Id1285 | B1055: =IF(A1055="?", "Unknown",A1055) -> Id1285 | C1055: 1975 | D1055: =IF(C1055="?",ROUND(AVERAGE($C$2:$C$2344),0),C1055) -> 1975 | E1055: Aug | F1055: =IF(E1055="?","Sep",E1055) -> Aug | G1055: 6 | H1055: =CONCATENATE(G1055,"-",F1055,"-",D1055) -> 6-Aug-1975 | I1055: 27612 | J1055: =DATEDIF(I1055,"8-6-2023","Y") -> 47 | K1055: 1 | L1055: 8551.35 | M1055: tier - 2 | N1055: =MATCH(M1055,$M$2:$M$2344,0) -> 1 | O1055: =IF(M1055="?",INDEX($M$2:$M$2344,MODE($N$2:$N$2344)),M1055) -> tier - 2 | P1055: tier - 2 | Q1055: =MATCH(P1055,$P$2:$P$2344,0) -> 9 | R1055: =IF(P1055="?",INDEX($P$2:$P$2344,MODE($Q$2:$Q$2344)),P1055) -> tier - 2 | S1055: R1011 | T1055: =IF(S1055="?","Unknown",S1055) -> R1011
A1056: Id1284 | B1056: =IF(A1056="?", "Unknown",A1056) -> Id1284 | C1056: 1975 | D1056: =IF(C1056="?",ROUND(AVERAGE($C$2:$C$2344),0),C1056) -> 1975 | E1056: Aug | F1056: =IF(E1056="?","Sep",E1056) -> Aug | G1056: 21 | H1056: =CONCATENATE(G1056,"-",F1056,"-",D1056) -> 21-Aug-1975 | I1056: 27627 | J1056: =DATEDIF(I1056,"8-6-2023","Y") -> 47 | K1056: 1 | L1056: 8556.91 | M1056: tier - 2 | N1056: =MATCH(M1056,$M$2:$M$2344,0) -> 1 | O1056: =IF(M1056="?",INDEX($M$2:$M$2344,MODE($N$2:$N$2344)),M1056) -> tier - 2 | P1056: tier - 1 | Q1056: =MATCH(P1056,$P$2:$P$2344,0) -> 2 | R1056: =IF(P1056="?",INDEX($P$2:$P$2344,MODE($Q$2:$Q$2344)),P1056) -> tier - 1 | S1056: R1011 | T1056: =IF(S1056="?","Unknown",S1056) -> R1011
A1057: Id1283 | B1057: =IF(A1057="?", "Unknown",A1057) -> Id1283 | C1057: 1988 | D1057: =IF(C1057="?",ROUND(AVERAGE($C$2:$C$2344),0),C1057) -> 1988 | E1057: Sep | F1057: =IF(E1057="?","Sep",E1057) -> Sep | G1057: 21 | H1057: =CONCATENATE(G1057,"-",F1057,"-",D1057) -> 21-Sep-1988 | I1057: 32407 | J1057: =DATEDIF(I1057,"8-6-2023","Y") -> 34 | K1057: 3 | L1057: 8567.25 | M1057: tier - 2 | N1057: =MATCH(M1057,$M$2:$M$2344,0) -> 1 | O1057: =IF(M1057="?",INDEX($M$2:$M$2344,MODE($N$2:$N$2344)),M1057) -> tier - 2 | P1057: tier - 1 | Q1057: =MATCH(P1057,$P$2:$P$2344,0) -> 2 | R1057: =IF(P1057="?",INDEX($P$2:$P$2344,MODE($Q$2:$Q$2344)),P1057) -> tier - 1 | S1057: R1012 | T1057: =IF(S1057="?","Unknown",S1057) -> R1012
A1058: Id1282 | B1058: =IF(A1058="?", "Unknown",A1058) -> Id1282 | C1058: 1975 | D1058: =IF(C1058="?",ROUND(AVERAGE($C$2:$C$2344),0),C1058) -> 1975 | E1058: Sep | F1058: =IF(E1058="?","Sep",E1058) -> Sep | G1058: 26 | H1058: =CONCATENATE(G1058,"-",F1058,"-",D1058) -> 26-Sep-1975 | I1058: 27663 | J1058: =DATEDIF(I1058,"8-6-2023","Y") -> 47 | K1058: 1 | L1058: 8569.86 | M1058: tier - 2 | N1058: =MATCH(M1058,$M$2:$M$2344,0) -> 1 | O1058: =IF(M1058="?",INDEX($M$2:$M$2344,MODE($N$2:$N$2344)),M1058) -> tier - 2 | P1058: tier - 3 | Q1058: =MATCH(P1058,$P$2:$P$2344,0) -> 1 | R1058: =IF(P1058="?",INDEX($P$2:$P$2344,MODE($Q$2:$Q$2344)),P1058) -> tier - 3 | S1058: R1013 | T1058: =IF(S1058="?","Unknown",S1058) -> R1013
A1059: Id1281 | B1059: =IF(A1059="?", "Unknown",A1059) -> Id1281 | C1059: 1982 | D1059: =IF(C1059="?",ROUND(AVERAGE($C$2:$C$2344),0),C1059) -> 1982 | E1059: Dec | F1059: =IF(E1059="?","Sep",E1059) -> Dec | G1059: 6 | H1059: =CONCATENATE(G1059,"-",F1059,"-",D1059) -> 6-Dec-1982 | I1059: 30291 | J1059: =DATEDIF(I1059,"8-6-2023","Y") -> 40 | K1059: 3 | L1059: 8572.04 | M1059: tier - 2 | N1059: =MATCH(M1059,$M$2:$M$2344,0) -> 1 | O1059: =IF(M1059="?",INDEX($M$2:$M$2344,MODE($N$2:$N$2344)),M1059) -> tier - 2 | P1059: tier - 2 | Q1059: =MATCH(P1059,$P$2:$P$2344,0) -> 9 | R1059: =IF(P1059="?",INDEX($P$2:$P$2344,MODE($Q$2:$Q$2344)),P1059) -> tier - 2 | S1059: R1021 | T1059: =IF(S1059="?","Unknown",S1059) -> R1021
A1060: Id1280 | B1060: =IF(A1060="?", "Unknown",A1060) -> Id1280 | C1060: 1987 | D1060: =IF(C1060="?",ROUND(AVERAGE($C$2:$C$2344),0),C1060) -> 1987 | E1060: Nov | F1060: =IF(E1060="?","Sep",E1060) -> Nov | G1060: 11 | H1060: =CONCATENATE(G1060,"-",F1060,"-",D1060) -> 11-Nov-1987 | I1060: 32092 | J1060: =DATEDIF(I1060,"8-6-2023","Y") -> 35 | K1060: 3 | L1060: 8573.3 | M1060: tier - 2 | N1060: =MATCH(M1060,$M$2:$M$2344,0) -> 1 | O1060: =IF(M1060="?",INDEX($M$2:$M$2344,MODE($N$2:$N$2344)),M1060) -> tier - 2 | P1060: tier - 2 | Q1060: =MATCH(P1060,$P$2:$P$2344,0) -> 9 | R1060: =IF(P1060="?",INDEX($P$2:$P$2344,MODE($Q$2:$Q$2344)),P1060) -> tier - 2 | S1060: R1021 | T1060: =IF(S1060="?","Unknown",S1060) -> R1021
A1061: Id1279 | B1061: =IF(A1061="?", "Unknown",A1061) -> Id1279 | C1061: 1983 | D1061: =IF(C1061="?",ROUND(AVERAGE($C$2:$C$2344),0),C1061) -> 1983 | E1061: Dec | F1061: =IF(E1061="?","Sep",E1061) -> Dec | G1061: 30 | H1061: =CONCATENATE(G1061,"-",F1061,"-",D1061) -> 30-Dec-1983 | I1061: 30680 | J1061: =DATEDIF(I1061,"8-6-2023","Y") -> 39 | K1061: 5 | L1061: 8582.3 | M1061: tier - 2 | N1061: =MATCH(M1061,$M$2:$M$2344,0) -> 1 | O1061: =IF(M1061="?",INDEX($M$2:$M$2344,MODE($N$2:$N$2344)),M1061) -> tier - 2 | P1061: tier - 1 | Q1061: =MATCH(P1061,$P$2:$P$2344,0) -> 2 | R1061: =IF(P1061="?",INDEX($P$2:$P$2344,MODE($Q$2:$Q$2344)),P1061) -> tier - 1 | S1061: R1013 | T1061: =IF(S1061="?","Unknown",S1061) -> R1013
A1062: Id1278 | B1062: =IF(A1062="?", "Unknown",A1062) -> Id1278 | C1062: 1983 | D1062: =IF(C1062="?",ROUND(AVERAGE($C$2:$C$2344),0),C1062) -> 1983 | E1062: Jul | F1062: =IF(E1062="?","Sep",E1062) -> Jul | G1062: 25 | H1062: =CONCATENATE(G1062,"-",F1062,"-",D1062) -> 25-Jul-1983 | I1062: 30522 | J1062: =DATEDIF(I1062,"8-6-2023","Y") -> 39 | K1062: 5 | L1062: 8596.83 | M1062: tier - 2 | N1062: =MATCH(M1062,$M$2:$M$2344,0) -> 1 | O1062: =IF(M1062="?",INDEX($M$2:$M$2344,MODE($N$2:$N$2344)),M1062) -> tier - 2 | P1062: tier - 3 | Q1062: =MATCH(P1062,$P$2:$P$2344,0) -> 1 | R1062: =IF(P1062="?",INDEX($P$2:$P$2344,MODE($Q$2:$Q$2344)),P1062) -> tier - 3 | S1062: R1013 | T1062: =IF(S1062="?","Unknown",S1062) -> R1013
A1063: Id1277 | B1063: =IF(A1063="?", "Unknown",A1063) -> Id1277 | C1063: 1973 | D1063: =IF(C1063="?",ROUND(AVERAGE($C$2:$C$2344),0),C1063) -> 1973 | E1063: Jul | F1063: =IF(E1063="?","Sep",E1063) -> Jul | G1063: 11 | H1063: =CONCATENATE(G1063,"-",F1063,"-",D1063) -> 11-Jul-1973 | I1063: 26856 | J1063: =DATEDIF(I1063,"8-6-2023","Y") -> 49 | K1063: 0 | L1063: 8601.33 | M1063: tier - 2 | N1063: =MATCH(M1063,$M$2:$M$2344,0) -> 1 | O1063: =IF(M1063="?",INDEX($M$2:$M$2344,MODE($N$2:$N$2344)),M1063) -> tier - 2 | P1063: tier - 1 | Q1063: =MATCH(P1063,$P$2:$P$2344,0) -> 2 | R1063: =IF(P1063="?",INDEX($P$2:$P$2344,MODE($Q$2:$Q$2344)),P1063) -> tier - 1 | S1063: R1013 | T1063: =IF(S1063="?","Unknown",S1063) -> R1013
A1064: Id1276 | B1064: =IF(A1064="?", "Unknown",A1064) -> Id1276 | C1064: 1977 | D1064: =IF(C1064="?",ROUND(AVERAGE($C$2:$C$2344),0),C1064) -> 1977 | E1064: Sep | F1064: =IF(E1064="?","Sep",E1064) -> Sep | G1064: 24 | H1064: =CONCATENATE(G1064,"-",F1064,"-",D1064) -> 24-Sep-1977 | I1064: 28392 | J1064: =DATEDIF(I1064,"8-6-2023","Y") -> 45 | K1064: 2 | L1064: 8603.82 | M1064: tier - 2 | N1064: =MATCH(M1064,$M$2:$M$2344,0) -> 1 | O1064: =IF(M1064="?",INDEX($M$2:$M$2344,MODE($N$2:$N$2344)),M1064) -> tier - 2 | P1064: tier - 1 | Q1064: =MATCH(P1064,$P$2:$P$2344,0) -> 2 | R1064: =IF(P1064="?",INDEX($P$2:$P$2344,MODE($Q$2:$Q$2344)),P1064) -> tier - 1 | S1064: R1019 | T1064: =IF(S1064="?","Unknown",S1064) -> R1019
A1065: Id1275 | B1065: =IF(A1065="?", "Unknown",A1065) -> Id1275 | C1065: 1977 | D1065: =IF(C1065="?",ROUND(AVERAGE($C$2:$C$2344),0),C1065) -> 1977 | E1065: Nov | F1065: =IF(E1065="?","Sep",E1065) -> Nov | G1065: 12 | H1065: =CONCATENATE(G1065,"-",F1065,"-",D1065) -> 12-Nov-1977 | I1065: 28441 | J1065: =DATEDIF(I1065,"8-6-2023","Y") -> 45 | K1065: 2 | L1065: 8604.48 | M1065: tier - 3 | N1065: =MATCH(M1065,$M$2:$M$2344,0) -> 4 | O1065: =IF(M1065="?",INDEX($M$2:$M$2344,MODE($N$2:$N$2344)),M1065) -> tier - 3 | P1065: tier - 2 | Q1065: =MATCH(P1065,$P$2:$P$2344,0) -> 9 | R1065: =IF(P1065="?",INDEX($P$2:$P$2344,MODE($Q$2:$Q$2344)),P1065) -> tier - 2 | S1065: R1016 | T1065: =IF(S1065="?","Unknown",S1065) -> R1016
A1066: Id1274 | B1066: =IF(A1066="?", "Unknown",A1066) -> Id1274 | C1066: 1977 | D1066: =IF(C1066="?",ROUND(AVERAGE($C$2:$C$2344),0),C1066) -> 1977 | E1066: Oct | F1066: =IF(E1066="?","Sep",E1066) -> Oct | G1066: 15 | H1066: =CONCATENATE(G1066,"-",F1066,"-",D1066) -> 15-Oct-1977 | I1066: 28413 | J1066: =DATEDIF(I1066,"8-6-2023","Y") -> 45 | K1066: 3 | L1066: 8605.36 | M1066: tier - 2 | N1066: =MATCH(M1066,$M$2:$M$2344,0) -> 1 | O1066: =IF(M1066="?",INDEX($M$2:$M$2344,MODE($N$2:$N$2344)),M1066) -> tier - 2 | P1066: tier - 2 | Q1066: =MATCH(P1066,$P$2:$P$2344,0) -> 9 | R1066: =IF(P1066="?",INDEX($P$2:$P$2344,MODE($Q$2:$Q$2344)),P1066) -> tier - 2 | S1066: R1013 | T1066: =IF(S1066="?","Unknown",S1066) -> R1013
... A2344: Id1 | B2344: =IF(A2344="?", "Unknown",A2344) -> Id1 | C2344: 1968 | D2344: =IF(C2344="?",ROUND(AVERAGE($C$2:$C$2344),0),C2344) -> 1968 | E2344: Oct | F2344: =IF(E2344="?","Sep",E2344) -> Oct | G2344: 12 | H2344: =CONCATENATE(G2344,"-",F2344,"-",D2344) -> 12-Oct-1968 | I2344: 25123 | J2344: =DATEDIF(I2344,"8-6-2023","Y") -> 54 | K2344: 0 | L2344: 63770.43 | M2344: tier - 1 | N2344: =MATCH(M2344,$M$2:$M$2344,0) -> 240 | O2344: =IF(M2344="?",INDEX($M$2:$M$2344,MODE($N$2:$N$2344)),M2344) -> tier - 1 | P2344: tier - 3 | Q2344: =MATCH(P2344,$P$2:$P$2344,0) -> 1 | R2344: =IF(P2344="?",INDEX($P$2:$P$2344,MODE($Q$2:$Q$2344)),P2344) -> tier - 3 | S2344: R1013 | T2344: =IF(S2344="?","Unknown",S2344) -> R1013

Sheet Healthcare
A1: Customer ID | B1: =VLOOKUP(A1,'Customer Names'!$A$1:$E$2336,4,0) -> First Name | C1: Date of Birth | D1: Age | E1: Children | F1: =VLOOKUP(A1,'Medical Examinations'!$A$1:$L$2336,2,0) -> BMI | G1: =VLOOKUP(A1,'Medical Examinations'!$A$1:$L$2336,4,0) -> HBA1C | H1: =VLOOKUP(A1,'Medical Examinations'!$A$1:$L$2336,3,0) -> Weight Status | I1: =VLOOKUP(A1,'Medical Examinations'!$A$1:$L$2336,5,0) -> Diabetes status | J1: =VLOOKUP(A1,'Medical Examinations'!$A$1:$L$2336,6,0) -> Heart Issues | K1: =VLOOKUP(A1,'Medical Examinations'!$A$1:$L$2336,7,0) -> Any Transplants | L1: No. of surgeries | M1: Smoker | N1: Cancer History | O1: Charges | P1: Hospital Tier | Q1: City Tier | R1: State ID
A2: Id1 | B2: =VLOOKUP(A2,'Customer Names'!A2:$E$2335,4,0) -> Hawks | C2: =VLOOKUP(A2,'Hospitalisation Details'!$A$1:$T$2344,9,0) -> 25123 | D2: =VLOOKUP(A2,'Hospitalisation Details'!$A$1:$T$2344,10,0) -> 54 | E2: =VLOOKUP(A2,'Hospitalisation Details'!$A$1:$T$2344,11,0) -> 0 | F2: =VLOOKUP(A2,'Medical Examinations'!$A$1:$L$2336,2,0) -> 47.41 | G2: =VLOOKUP(A2,'Medical Examinations'!$A$1:$L$2336,4,0) -> 7.47 | H2: =VLOOKUP(A2,'Medical Examinations'!$A$1:$L$2336,3,0) -> Obesity | I2: =VLOOKUP(A2,'Medical Examinations'!$A$1:$L$2336,5,0) -> Diabetes | J2: =VLOOKUP(A2,'Medical Examinations'!$A$1:$L$2336,6,0) -> No | K2: =VLOOKUP(A2,'Medical Examinations'!$A$1:$L$2336,7,0) -> No | L2: =VLOOKUP(A2,'Medical Examinations'!$A$1:$L$2336,10,0) -> 0 | M2: =VLOOKUP(A2,'Medical Examinations'!$A$1:$L$2336,12,0) -> yes | N2: =VLOOKUP(A2,'Medical Examinations'!$A$1:$L$2336,8,0) -> No | O2: =VLOOKUP(A2,'Hospitalisation Details'!$A$1:$T$2344,12,0) -> 63770.43 | P2: =VLOOKUP(A2,'Hospitalisation Details'!$A$1:$T$2344,15,0) -> tier - 1 | Q2: =VLOOKUP(A2,'Hospitalisation Details'!$A$1:$T$2344,18,0) -> tier - 3 | R2: =VLOOKUP(A2,'Hospitalisation Details'!$A$1:$T$2344,20,0) -> R1013
A3: Id2 | B3: =VLOOKUP(A3,'Customer Names'!A3:$E$2335,4,0) -> Lehner | C3: =VLOOKUP(A3,'Hospitalisation Details'!$A$1:$T$2344,9,0) -> 28284 | D3: =VLOOKUP(A3,'Hospitalisation Details'!$A$1:$T$2344,10,0) -> 46 | E3: =VLOOKUP(A3,'Hospitalisation Details'!$A$1:$T$2344,11,0) -> 0 | F3: =VLOOKUP(A3,'Medical Examinations'!$A$1:$L$2336,2,0) -> 30.36 | G3: =VLOOKUP(A3,'Medical Examinations'!$A$1:$L$2336,4,0) -> 5.77 | H3: =VLOOKUP(A3,'Medical Examinations'!$A$1:$L$2336,3,0) -> Obesity | I3: =VLOOKUP(A3,'Medical Examinations'!$A$1:$L$2336,5,0) -> Pre-diabetes | J3: =VLOOKUP(A3,'Medical Examinations'!$A$1:$L$2336,6,0) -> No | K3: =VLOOKUP(A3,'Medical Examinations'!$A$1:$L$2336,7,0) -> No | L3: =VLOOKUP(A3,'Medical Examinations'!$A$1:$L$2336,10,0) -> 0 | M3: =VLOOKUP(A3,'Medical Examinations'!$A$1:$L$2336,12,0) -> yes | N3: =VLOOKUP(A3,'Medical Examinations'!$A$1:$L$2336,8,0) -> No | O3: =VLOOKUP(A3,'Hospitalisation Details'!$A$1:$T$2344,12,0) -> 62592.87 | P3: =VLOOKUP(A3,'Hospitalisation Details'!$A$1:$T$2344,15,0) -> tier - 2 | Q3: =VLOOKUP(A3,'Hospitalisation Details'!$A$1:$T$2344,18,0) -> tier - 3 | R3: =VLOOKUP(A3,'Hospitalisation Details'!$A$1:$T$2344,20,0) -> R1013
A4: Id3 | B4: =VLOOKUP(A4,'Customer Names'!A4:$E$2335,4,0) -> Lu | C4: =VLOOKUP(A4,'Hospitalisation Details'!$A$1:$T$2344,9,0) -> 25822 | D4: =VLOOKUP(A4,'Hospitalisation Details'!$A$1:$T$2344,10,0) -> 52 | E4: =VLOOKUP(A4,'Hospitalisation Details'!$A$1:$T$2344,11,0) -> 3 | F4: =VLOOKUP(A4,'Medical Examinations'!$A$1:$L$2336,2,0) -> 34.485 | G4: =VLOOKUP(A4,'Medical Examinations'!$A$1:$L$2336,4,0) -> 11.87 | H4: =VLOOKUP(A4,'Medical Examinations'!$A$1:$L$2336,3,0) -> Obesity | I4: =VLOOKUP(A4,'Medical Examinations'!$A$1:$L$2336,5,0) -> Diabetes | J4: =VLOOKUP(A4,'Medical Examinations'!$A$1:$L$2336,6,0) -> yes | K4: =VLOOKUP(A4,'Medical Examinations'!$A$1:$L$2336,7,0) -> No | L4: =VLOOKUP(A4,'Medical Examinations'!$A$1:$L$2336,10,0) -> 2 | M4: =VLOOKUP(A4,'Medical Examinations'!$A$1:$L$2336,12,0) -> yes | N4: =VLOOKUP(A4,'Medical Examinations'!$A$1:$L$2336,8,0) -> No | O4: =VLOOKUP(A4,'Hospitalisation Details'!$A$1:$T$2344,12,0) -> 60021.4 | P4: =VLOOKUP(A4,'Hospitalisation Details'!$A$1:$T$2344,15,0) -> tier - 1 | Q4: =VLOOKUP(A4,'Hospitalisation Details'!$A$1:$T$2344,18,0) -> tier - 1 | R4: =VLOOKUP(A4,'Hospitalisation Details'!$A$1:$T$2344,20,0) -> R1012
A5: Id4 | B5: =VLOOKUP(A5,'Customer Names'!A5:$E$2335,4,0) -> Osborne | C5: =VLOOKUP(A5,'Hospitalisation Details'!$A$1:$T$2344,9,0) -> 33395 | D5: =VLOOKUP(A5,'Hospitalisation Details'!$A$1:$T$2344,10,0) -> 32 | E5: =VLOOKUP(A5,'Hospitalisation Details'!$A$1:$T$2344,11,0) -> 1 | F5: =VLOOKUP(A5,'Medical Examinations'!$A$1:$L$2336,2,0) -> 38.095 | G5: =VLOOKUP(A5,'Medical Examinations'!$A$1:$L$2336,4,0) -> 6.05 | H5: =VLOOKUP(A5,'Medical Examinations'!$A$1:$L$2336,3,0) -> Obesity | I5: =VLOOKUP(A5,'Medical Examinations'!$A$1:$L$2336,5,0) -> Pre-diabetes | J5: =VLOOKUP(A5,'Medical Examinations'!$A$1:$L$2336,6,0) -> No | K5: =VLOOKUP(A5,'Medical Examinations'!$A$1:$L$2336,7,0) -> No | L5: =VLOOKUP(A5,'Medical Examinations'!$A$1:$L$2336,10,0) -> 0 | M5: =VLOOKUP(A5,'Medical Examinations'!$A$1:$L$2336,12,0) -> yes | N5: =VLOOKUP(A5,'Medical Examinations'!$A$1:$L$2336,8,0) -> No | O5: =VLOOKUP(A5,'Hospitalisation Details'!$A$1:$T$2344,12,0) -> 58571.07 | P5: =VLOOKUP(A5,'Hospitalisation Details'!$A$1:$T$2344,15,0) -> tier - 1 | Q5: =VLOOKUP(A5,'Hospitalisation Details'!$A$1:$T$2344,18,0) -> tier - 3 | R5: =VLOOKUP(A5,'Hospitalisation Details'!$A$1:$T$2344,20,0) -> R1024
A6: Id5 | B6: =VLOOKUP(A6,'Customer Names'!A6:$E$2335,4,0) -> Kadala | C6: =VLOOKUP(A6,'Hospitalisation Details'!$A$1:$T$2344,9,0) -> 32678 | D6: =VLOOKUP(A6,'Hospitalisation Details'!$A$1:$T$2344,10,0) -> 33 | E6: =VLOOKUP(A6,'Hospitalisation Details'!$A$1:$T$2344,11,0) -> 0 | F6: =VLOOKUP(A6,'Medical Examinations'!$A$1:$L$2336,2,0) -> 35.53 | G6: =VLOOKUP(A6,'Medical Examinations'!$A$1:$L$2336,4,0) -> 5.45 | H6: =VLOOKUP(A6,'Medical Examinations'!$A$1:$L$2336,3,0) -> Obesity | I6: =VLOOKUP(A6,'Medical Examinations'!$A$1:$L$2336,5,0) -> Normal | J6: =VLOOKUP(A6,'Medical Examinations'!$A$1:$L$2336,6,0) -> No | K6: =VLOOKUP(A6,'Medical Examinations'!$A$1:$L$2336,7,0) -> No | L6: =VLOOKUP(A6,'Medical Examinations'!$A$1:$L$2336,10,0) -> 0 | M6: =VLOOKUP(A6,'Medical Examinations'!$A$1:$L$2336,12,0) -> yes | N6: =VLOOKUP(A6,'Medical Examinations'!$A$1:$L$2336,8,0) -> No | O6: =VLOOKUP(A6,'Hospitalisation Details'!$A$1:$T$2344,12,0) -> 55135.4 | P6: =VLOOKUP(A6,'Hospitalisation Details'!$A$1:$T$2344,15,0) -> tier - 1 | Q6: =VLOOKUP(A6,'Hospitalisation Details'!$A$1:$T$2344,18,0) -> tier - 2 | R6: =VLOOKUP(A6,'Hospitalisation Details'!$A$1:$T$2344,20,0) -> R1012
A7: Id6 | B7: =VLOOKUP(A7,'Customer Names'!A7:$E$2335,4,0) -> Baker | C7: =VLOOKUP(A7,'Hospitalisation Details'!$A$1:$T$2344,9,0) -> 22862 | D7: =VLOOKUP(A7,'Hospitalisation Details'!$A$1:$T$2344,10,0) -> 60 | E7: =VLOOKUP(A7,'Hospitalisation Details'!$A$1:$T$2344,11,0) -> 0 | F7: =VLOOKUP(A7,'Medical Examinations'!$A$1:$L$2336,2,0) -> 32.8 | G7: =VLOOKUP(A7,'Medical Examinations'!$A$1:$L$2336,4,0) -> 6.59 | H7: =VLOOKUP(A7,'Medical Examinations'!$A$1:$L$2336,3,0) -> Obesity | I7: =VLOOKUP(A7,'Medical Examinations'!$A$1:$L$2336,5,0) -> Diabetes | J7: =VLOOKUP(A7,'Medical Examinations'!$A$1:$L$2336,6,0) -> No | K7: =VLOOKUP(A7,'Medical Examinations'!$A$1:$L$2336,7,0) -> No | L7: =VLOOKUP(A7,'Medical Examinations'!$A$1:$L$2336,10,0) -> 0 | M7: =VLOOKUP(A7,'Medical Examinations'!$A$1:$L$2336,12,0) -> yes | N7: =VLOOKUP(A7,'Medical Examinations'!$A$1:$L$2336,8,0) -> No | O7: =VLOOKUP(A7,'Hospitalisation Details'!$A$1:$T$2344,12,0) -> 52590.83 | P7: =VLOOKUP(A7,'Hospitalisation Details'!$A$1:$T$2344,15,0) -> tier - 1 | Q7: =VLOOKUP(A7,'Hospitalisation Details'!$A$1:$T$2344,18,0) -> tier - 3 | R7: =VLOOKUP(A7,'Hospitalisation Details'!$A$1:$T$2344,20,0) -> R1011
A8: Id7 | B8: =VLOOKUP(A8,'Customer Names'!A8:$E$2335,4,0) -> Macpherson | C8: =VLOOKUP(A8,'Hospitalisation Details'!$A$1:$T$2344,9,0) -> 34634 | D8: =VLOOKUP(A8,'Hospitalisation Details'!$A$1:$T$2344,10,0) -> 28 | E8: =VLOOKUP(A8,'Hospitalisation Details'!$A$1:$T$2344,11,0) -> 1 | F8: =VLOOKUP(A8,'Medical Examinations'!$A$1:$L$2336,2,0) -> 36.4 | G8: =VLOOKUP(A8,'Medical Examinations'!$A$1:$L$2336,4,0) -> 6.07 | H8: =VLOOKUP(A8,'Medical Examinations'!$A$1:$L$2336,3,0) -> Obesity | I8: =VLOOKUP(A8,'Medical Examinations'!$A$1:$L$2336,5,0) -> Pre-diabetes | J8: =VLOOKUP(A8,'Medical Examinations'!$A$1:$L$2336,6,0) -> No | K8: =VLOOKUP(A8,'Medical Examinations'!$A$1:$L$2336,7,0) -> No | L8: =VLOOKUP(A8,'Medical Examinations'!$A$1:$L$2336,10,0) -> 0 | M8: =VLOOKUP(A8,'Medical Examinations'!$A$1:$L$2336,12,0) -> yes | N8: =VLOOKUP(A8,'Medical Examinations'!$A$1:$L$2336,8,0) -> No | O8: =VLOOKUP(A8,'Hospitalisation Details'!$A$1:$T$2344,12,0) -> 51194.56 | P8: =VLOOKUP(A8,'Hospitalisation Details'!$A$1:$T$2344,15,0) -> tier - 1 | Q8: =VLOOKUP(A8,'Hospitalisation Details'!$A$1:$T$2344,18,0) -> tier - 3 | R8: =VLOOKUP(A8,'Hospitalisation Details'!$A$1:$T$2344,20,0) -> R1011
A9: Id8 | B9: =VLOOKUP(A9,'Customer Names'!A9:$E$2335,4,0) -> Hallman | C9: =VLOOKUP(A9,'Hospitalisation Details'!$A$1:$T$2344,9,0) -> 21363 | D9: =VLOOKUP(A9,'Hospitalisation Details'!$A$1:$T$2344,10,0) -> 64 | E9: =VLOOKUP(A9,'Hospitalisation Details'!$A$1:$T$2344,11,0) -> 2 | F9: =VLOOKUP(A9,'Medical Examinations'!$A$1:$L$2336,2,0) -> 36.96 | G9: =VLOOKUP(A9,'Medical Examinations'!$A$1:$L$2336,4,0) -> 7.93 | H9: =VLOOKUP(A9,'Medical Examinations'!$A$1:$L$2336,3,0) -> Obesity | I9: =VLOOKUP(A9,'Medical Examinations'!$A$1:$L$2336,5,0) -> Diabetes | J9: =VLOOKUP(A9,'Medical Examinations'!$A$1:$L$2336,6,0) -> No | K9: =VLOOKUP(A9,'Medical Examinations'!$A$1:$L$2336,7,0) -> No | L9: =VLOOKUP(A9,'Medical Examinations'!$A$1:$L$2336,10,0) -> 3 | M9: =VLOOKUP(A9,'Medical Examinations'!$A$1:$L$2336,12,0) -> yes | N9: =VLOOKUP(A9,'Medical Examinations'!$A$1:$L$2336,8,0) -> No | O9: =VLOOKUP(A9,'Hospitalisation Details'!$A$1:$T$2344,12,0) -> 49577.66 | P9: =VLOOKUP(A9,'Hospitalisation Details'!$A$1:$T$2344,15,0) -> tier - 2 | Q9: =VLOOKUP(A9,'Hospitalisation Details'!$A$1:$T$2344,18,0) -> tier - 2 | R9: =VLOOKUP(A9,'Hospitalisation Details'!$A$1:$T$2344,20,0) -> R1013
A10: Id9 | B10: =VLOOKUP(A10,'Customer Names'!A10:$E$2335,4,0) -> Moran | C10: =VLOOKUP(A10,'Hospitalisation Details'!$A$1:$T$2344,9,0) -> 23258 | D10: =VLOOKUP(A10,'Hospitalisation Details'!$A$1:$T$2344,10,0) -> 59 | E10: =VLOOKUP(A10,'Hospitalisation Details'!$A$1:$T$2344,11,0) -> 1 | F10: =VLOOKUP(A10,'Medical Examinations'!$A$1:$L$2336,2,0) -> 41.14 | G10: =VLOOKUP(A10,'Medical Examinations'!$A$1:$L$2336,4,0) -> 9.58 | H10: =VLOOKUP(A10,'Medical Examinations'!$A$1:$L$2336,3,0) -> Obesity | I10: =VLOOKUP(A10,'Medical Examinations'!$A$1:$L$2336,5,0) -> Diabetes | J10: =VLOOKUP(A10,'Medical Examinations'!$A$1:$L$2336,6,0) -> yes | K10: =VLOOKUP(A10,'Medical Examinations'!$A$1:$L$2336,7,0) -> No | L10: =VLOOKUP(A10,'Medical Examinations'!$A$1:$L$2336,10,0) -> 1 | M10: =VLOOKUP(A10,'Medical Examinations'!$A$1:$L$2336,12,0) -> yes | N10: =VLOOKUP(A10,'Medical Examinations'!$A$1:$L$2336,8,0) -> Yes | O10: =VLOOKUP(A10,'Hospitalisation Details'!$A$1:$T$2344,12,0) -> 48970.25 | P10: =VLOOKUP(A10,'Hospitalisation Details'!$A$1:$T$2344,15,0) -> tier - 1 | Q10: =VLOOKUP(A10,'Hospitalisation Details'!$A$1:$T$2344,18,0) -> tier - 2 | R10: =VLOOKUP(A10,'Hospitalisation Details'!$A$1:$T$2344,20,0) -> R1013
A11: Id10 | B11: =VLOOKUP(A11,'Customer Names'!A11:$E$2335,4,0) -> Benner | C11: =VLOOKUP(A11,'Hospitalisation Details'!$A$1:$T$2344,9,0) -> 28853 | D11: =VLOOKUP(A11,'Hospitalisation Details'!$A$1:$T$2344,10,0) -> 44 | E11: =VLOOKUP(A11,'Hospitalisation Details'!$A$1:$T$2344,11,0) -> 0 | F11: =VLOOKUP(A11,'Medical Examinations'!$A$1:$L$2336,2,0) -> 38.06 | G11: =VLOOKUP(A11,'Medical Examinations'!$A$1:$L$2336,4,0) -> 10.79 | H11: =VLOOKUP(A11,'Medical Examinations'!$A$1:$L$2336,3,0) -> Obesity | I11: =VLOOKUP(A11,'Medical Examinations'!$A$1:$L$2336,5,0) -> Diabetes | J11: =VLOOKUP(A11,'Medical Examinations'!$A$1:$L$2336,6,0) -> No | K11: =VLOOKUP(A11,'Medical Examinations'!$A$1:$L$2336,7,0) -> No | L11: =VLOOKUP(A11,'Medical Examinations'!$A$1:$L$2336,10,0) -> 0 | M11: =VLOOKUP(A11,'Medical Examinations'!$A$1:$L$2336,12,0) -> yes | N11: =VLOOKUP(A11,'Medical Examinations'!$A$1:$L$2336,8,0) -> No | O11: =VLOOKUP(A11,'Hospitalisation Details'!$A$1:$T$2344,12,0) -> 48885.14 | P11: =VLOOKUP(A11,'Hospitalisation Details'!$A$1:$T$2344,15,0) -> tier - 1 | Q11: =VLOOKUP(A11,'Hospitalisation Details'!$A$1:$T$2344,18,0) -> tier - 2 | R11: =VLOOKUP(A11,'Hospitalisation Details'!$A$1:$T$2344,20,0) -> R1013
A12: Id11 | B12: =VLOOKUP(A12,'Customer Names'!A12:$E$2335,4,0) -> Fierro Vargas | C12: =VLOOKUP(A12,'Hospitalisation Details'!$A$1:$T$2344,9,0) -> 21753 | D12: =VLOOKUP(A12,'Hospitalisation Details'!$A$1:$T$2344,10,0) -> 63 | E12: =VLOOKUP(A12,'Hospitalisation Details'!$A$1:$T$2344,11,0) -> 0 | F12: =VLOOKUP(A12,'Medical Examinations'!$A$1:$L$2336,2,0) -> 37.7 | G12: =VLOOKUP(A12,'Medical Examinations'!$A$1:$L$2336,4,0) -> 5.96 | H12: =VLOOKUP(A12,'Medical Examinations'!$A$1:$L$2336,3,0) -> Obesity | I12: =VLOOKUP(A12,'Medical Examinations'!$A$1:$L$2336,5,0) -> Pre-diabetes | J12: =VLOOKUP(A12,'Medical Examinations'!$A$1:$L$2336,6,0) -> yes | K12: =VLOOKUP(A12,'Medical Examinations'!$A$1:$L$2336,7,0) -> No | L12: =VLOOKUP(A12,'Medical Examinations'!$A$1:$L$2336,10,0) -> 2 | M12: =VLOOKUP(A12,'Medical Examinations'!$A$1:$L$2336,12,0) -> yes | N12: =VLOOKUP(A12,'Medical Examinations'!$A$1:$L$2336,8,0) -> No | O12: =VLOOKUP(A12,'Hospitalisation Details'!$A$1:$T$2344,12,0) -> 48824.45 | P12: =VLOOKUP(A12,'Hospitalisation Details'!$A$1:$T$2344,15,0) -> tier - 2 | Q12: =VLOOKUP(A12,'Hospitalisation Details'!$A$1:$T$2344,18,0) -> tier - 1 | R12: =VLOOKUP(A12,'Hospitalisation Details'!$A$1:$T$2344,20,0) -> R1011
A13: Id12 | B13: =VLOOKUP(A13,'Customer Names'!A13:$E$2335,4,0) -> Franz | C13: =VLOOKUP(A13,'Hospitalisation Details'!$A$1:$T$2344,9,0) -> 24042 | D13: =VLOOKUP(A13,'Hospitalisation Details'!$A$1:$T$2344,10,0) -> 57 | E13: =VLOOKUP(A13,'Hospitalisation Details'!$A$1:$T$2344,11,0) -> 1 | F13: =VLOOKUP(A13,'Medical Examinations'!$A$1:$L$2336,2,0) -> 42.13 | G13: =VLOOKUP(A13,'Medical Examinations'!$A$1:$L$2336,4,0) -> 11.9 | H13: =VLOOKUP(A13,'Medical Examinations'!$A$1:$L$2336,3,0) -> Obesity | I13: =VLOOKUP(A13,'Medical Examinations'!$A$1:$L$2336,5,0) -> Diabetes | J13: =VLOOKUP(A13,'Medical Examinations'!$A$1:$L$2336,6,0) -> No | K13: =VLOOKUP(A13,'Medical Examinations'!$A$1:$L$2336,7,0) -> No | L13: =VLOOKUP(A13,'Medical Examinations'!$A$1:$L$2336,10,0) -> 0 | M13: =VLOOKUP(A13,'Medical Examinations'!$A$1:$L$2336,12,0) -> yes | N13: =VLOOKUP(A13,'Medical Examinations'!$A$1:$L$2336,8,0) -> No | O13: =VLOOKUP(A13,'Hospitalisation Details'!$A$1:$T$2344,12,0) -> 48675.52 | P13: =VLOOKUP(A13,'Hospitalisation Details'!$A$1:$T$2344,15,0) -> tier - 1 | Q13: =VLOOKUP(A13,'Hospitalisation Details'!$A$1:$T$2344,18,0) -> tier - 2 | R13: =VLOOKUP(A13,'Hospitalisation Details'!$A$1:$T$2344,20,0) -> R1013
... A2335: Id2334 | B2335: =VLOOKUP(A2335,'Customer Names'!A2335:$E$2335,4,0) -> Rosendahl | C2335: =VLOOKUP(A2335,'Hospitalisation Details'!$A$1:$T$2344,9,0) -> 33938 | D2335: =VLOOKUP(A2335,'Hospitalisation Details'!$A$1:$T$2344,10,0) -> 30 | E2335: =VLOOKUP(A2335,'Hospitalisation Details'!$A$1:$T$2344,11,0) -> 0 | F2335: =VLOOKUP(A2335,'Medical Examinations'!$A$1:$L$2336,2,0) -> 17.6 | G2335: =VLOOKUP(A2335,'Medical Examinations'!$A$1:$L$2336,4,0) -> 4.39 | H2335: =VLOOKUP(A2335,'Medical Examinations'!$A$1:$L$2336,3,0) -> Underweight | I2335: =VLOOKUP(A2335,'Medical Examinations'!$A$1:$L$2336,5,0) -> Normal | J2335: =VLOOKUP(A2335,'Medical Examinations'!$A$1:$L$2336,6,0) -> No | K2335: =VLOOKUP(A2335,'Medical Examinations'!$A$1:$L$2336,7,0) -> No | L2335: =VLOOKUP(A2335,'Medical Examinations'!$A$1:$L$2336,10,0) -> 1 | M2335: =VLOOKUP(A2335,'Medical Examinations'!$A$1:$L$2336,12,0) -> No | N2335: =VLOOKUP(A2335,'Medical Examinations'!$A$1:$L$2336,8,0) -> No | O2335: =VLOOKUP(A2335,'Hospitalisation Details'!$A$1:$T$2344,12,0) -> 570.62 | P2335: =VLOOKUP(A2335,'Hospitalisation Details'!$A$1:$T$2344,15,0) -> tier - 2 | Q2335: =VLOOKUP(A2335,'Hospitalisation Details'!$A$1:$T$2344,18,0) -> tier - 1 | R2335: =VLOOKUP(A2335,'Hospitalisation Details'!$A$1:$T$2344,20,0) -> R1013
A2336: Id2335 | B2336: =VLOOKUP(A2336,'Customer Names'!A$2335:$E2336,4,0) -> German | C2336: =VLOOKUP(A2336,'Hospitalisation Details'!$A$1:$T$2344,9,0) -> 33794 | D2336: =VLOOKUP(A2336,'Hospitalisation Details'!$A$1:$T$2344,10,0) -> 30 | E2336: =VLOOKUP(A2336,'Hospitalisation Details'!$A$1:$T$2344,11,0) -> 0 | F2336: =VLOOKUP(A2336,'Medical Examinations'!$A$1:$L$2336,2,0) -> 17.58 | G2336: =VLOOKUP(A2336,'Medical Examinations'!$A$1:$L$2336,4,0) -> 4.51 | H2336: =VLOOKUP(A2336,'Medical Examinations'!$A$1:$L$2336,3,0) -> Underweight | I2336: =VLOOKUP(A2336,'Medical Examinations'!$A$1:$L$2336,5,0) -> Normal | J2336: =VLOOKUP(A2336,'Medical Examinations'!$A$1:$L$2336,6,0) -> No | K2336: =VLOOKUP(A2336,'Medical Examinations'!$A$1:$L$2336,7,0) -> No | L2336: =VLOOKUP(A2336,'Medical Examinations'!$A$1:$L$2336,10,0) -> 1 | M2336: =VLOOKUP(A2336,'Medical Examinations'!$A$1:$L$2336,12,0) -> No | N2336: =VLOOKUP(A2336,'Medical Examinations'!$A$1:$L$2336,8,0) -> No | O2336: =VLOOKUP(A2336,'Hospitalisation Details'!$A$1:$T$2344,12,0) -> 563.84 | P2336: =VLOOKUP(A2336,'Hospitalisation Details'!$A$1:$T$2344,15,0) -> tier - 2 | Q2336: =VLOOKUP(A2336,'Hospitalisation Details'!$A$1:$T$2344,18,0) -> tier - 3 | R2336: =VLOOKUP(A2336,'Hospitalisation Details'!$A$1:$T$2344,20,0) -> R1013

Sheet Manual Dashboard
I3: INSIGHT
A4: Particulars | B4: Cancer affected | C4: Cancer not affected | D4: cancer affected % | I4: SMOKER vs CANCER
A5: Smoker | B5: 84 | C5: 404 | D5: =Table13[[#This Row],[Cancer affected]]/GETPIVOTDATA("Smoker",$A$8,"Cancer History","Yes") -> 0.21483376 | F5: Row Labels | G5: Average of Charges
A6: Non smoker | B6: 307 | C6: 1540 | D6: =Table13[[#This Row],[Cancer affected]]/GETPIVOTDATA("Smoker",$A$8,"Cancer History","Yes") -> 0.78516624 | F6: Normal weight | G6: 9851.9225
F7: Obesity | G7: 16661.463
A8: Count of Smoker | B8: Column Labels | F8: Overweight | G8: 11435.413
A9: Row Labels | B9: No | C9: Yes | D9: Grand Total | F9: Underweight | G9: 6899.3175
A10: No | B10: 1540 | C10: 307 | D10: 1847 | F10: Grand Total | G10: 13529.918 | I10: WEIGHT STATUS vs CHARGES
